#VRML_SIM R2023b utf8

EXTERNPROTO "https://raw.githubusercontent.com/cyberbotics/webots/R2023b/projects/objects/backgrounds/protos/TexturedBackground.proto"
EXTERNPROTO "https://raw.githubusercontent.com/cyberbotics/webots/R2023b/projects/objects/backgrounds/protos/TexturedBackgroundLight.proto"
EXTERNPROTO "https://raw.githubusercontent.com/cyberbotics/webots/R2023b/projects/objects/floors/protos/RectangleArena.proto"
EXTERNPROTO "https://raw.githubusercontent.com/cyberbotics/webots/R2023b/projects/objects/factory/conveyors/protos/ConveyorBelt.proto"

WorldInfo {
}
Viewpoint {
  orientation -0.08259222468712775 0.0063170311287856435 0.9965634046757631 3.0490065159122115
  position 4.203829817809646 -0.23248423926098222 0.942343624983339
}
TexturedBackground {
}
TexturedBackgroundLight {
}
RectangleArena {
  translation 0 -0.01 0
  floorSize 10 10
}
Robot {
  translation 3.02 -0.24 0.45
  children [
    Solid {
      translation 0 0.24 0.35
      children [
        Camera {
          translation -1.46928e-07 0 -0.04
          rotation 0 1 0 1.5708
          recognition Recognition {
          }
        }
        Shape {
          appearance PBRAppearance {
            roughness 0.2
            metalness 0
          }
          geometry Cone {
            bottomRadius 0.05
            height 0.1
          }
        }
      ]
      name "solid(2)"
    }
    DEF base HingeJoint {
      jointParameters HingeJointParameters {
        axis 0 0 1
        anchor 0 0 0.0505
      }
      device [
        PositionSensor {
          name "ps1"
        }
        RotationalMotor {
          name "mot1"
          maxVelocity 1
        }
      ]
      endPoint Solid {
        translation 0 0 0.063
        children [
          DEF arm HingeJoint {
            jointParameters HingeJointParameters {
              axis -1 0 0
              anchor 0 0.026 0.0126
            }
            device [
              PositionSensor {
                name "ps2"
              }
              RotationalMotor {
                name "mot2"
                maxTorque 20
              }
            ]
            endPoint Solid {
              translation 4.547019999999976e-20 0.026000000000000006 0.11249999999999966
              rotation -2.754949216705333e-06 -0.9880485841314567 0.15414277598458492 1.7140869908987098e-06
              children [
                DEF forearmHinge HingeJoint {
                  jointParameters HingeJointParameters {
                    axis -1 0 0
                    anchor 0 0 0.1003
                  }
                  device [
                    PositionSensor {
                      name "ps3"
                    }
                    RotationalMotor {
                      name "mot3"
                    }
                  ]
                  endPoint Solid {
                    translation 0 -6.938893903907228e-18 0.2003
                    rotation -1 0 0 0
                    children [
                      HingeJoint {
                        jointParameters HingeJointParameters {
                          axis -1 0 0
                          anchor 0 0 0.1
                        }
                        device [
                          RotationalMotor {
                            name "wristMot"
                          }
                        ]
                        endPoint Solid {
                          translation 3.847562726777554e-05 -2.558304509813359e-05 0.11499506543746886
                          rotation 8.142675878921987e-06 0.176307842112959 -0.9843350774726911 5.156060168236875e-06
                          children [
                            HingeJoint {
                              jointParameters HingeJointParameters {
                                axis 0 0 1
                              }
                              device [
                                RotationalMotor {
                                }
                              ]
                              endPoint Solid {
                                translation 0 0 0.019999999999999626
                                children [
                                  SliderJoint {
                                    jointParameters JointParameters {
                                      axis -1 0 0
                                    }
                                    device [
                                      PositionSensor {
                                        name "finsen1"
                                      }
                                      LinearMotor {
                                        name "linMot2"
                                        maxPosition 0.04
                                      }
                                    ]
                                    endPoint Solid {
                                      translation -0.005 -1.1094e-16 0.01
                                      rotation -7.687554399613283e-05 0.9999999970425197 -2.2607634456952784e-06 3.6224422889367774e-12
                                      children [
                                        DEF finger Shape {
                                          geometry Box {
                                            size 0.01 0.01 0.01
                                          }
                                        }
                                      ]
                                      boundingObject USE finger
                                      physics Physics {
                                        density -1
                                        mass 0.01
                                      }
                                    }
                                  }
                                  SliderJoint {
                                    jointParameters JointParameters {
                                      axis 1 0 0
                                    }
                                    device [
                                      PositionSensor {
                                        name "finsen2"
                                      }
                                      LinearMotor {
                                        name "linMot1"
                                        maxPosition 0.04
                                      }
                                    ]
                                    endPoint Solid {
                                      translation 0.005 -1.11059e-16 0.01
                                      rotation -7.636695452546901e-05 -0.9999999970835234 -1.0204329734019837e-06 3.6224346705441156e-12
                                      children [
                                        USE finger
                                      ]
                                      name "solid(1)"
                                      boundingObject USE finger
                                      physics Physics {
                                        density -1
                                        mass 0.01
                                      }
                                    }
                                  }
                                  DEF hand Shape {
                                    appearance PBRAppearance {
                                      baseColor 0.5 0.5 0.5
                                      roughness 0.5
                                      metalness 0.2
                                    }
                                    geometry Box {
                                      size 0.1 0.01 0.01
                                    }
                                  }
                                ]
                                name "solid(2)"
                                boundingObject USE hand
                                physics Physics {
                                  density -1
                                  mass 0.01
                                }
                              }
                            }
                            DEF wrist Shape {
                              geometry Box {
                                size 0.02 0.02 0.03
                              }
                            }
                          ]
                          boundingObject USE wrist
                          physics Physics {
                            density -1
                            mass 0.01
                          }
                        }
                      }
                      DEF forearmShape Shape {
                        appearance PBRAppearance {
                          roughness 1
                          metalness 0.8
                        }
                        geometry Box {
                          size 0.02 0.02 0.2
                        }
                      }
                    ]
                    boundingObject USE forearmShape
                    physics Physics {
                      density -1
                      mass 0.15
                    }
                  }
                }
                DEF bicebs Shape {
                  appearance PBRAppearance {
                    baseColor 0.5 0.3 0.2
                    roughness 0.5
                  }
                  geometry Box {
                    size 0.02 0.02 0.2
                  }
                }
              ]
              boundingObject USE bicebs
              physics Physics {
                density -1
                mass 0.15
              }
            }
          }
          Shape {
            appearance PBRAppearance {
              metalness 0
            }
            geometry DEF base Box {
              size 0.15 0.05 0.025
            }
          }
        ]
        name "solid(1)"
        boundingObject USE base
        physics Physics {
          density -1
          mass 0.1
        }
      }
    }
    Solid {
      children [
        DEF box Shape {
          geometry Box {
            size 0.1 0.1 0.1
          }
        }
      ]
      boundingObject USE box
    }
  ]
  name "robot(1)"
  boundingObject USE box
  controller "epuck_go_forward"
}
ConveyorBelt {
  translation 2.48 0 0
  size 2.5 0.3 0.5
  speed 0
}
Robot {
  translation 2.53 0 0.84
  children [
    Camera {
      translation -1.46928e-07 0 -0.04
      rotation 0 1 0 1.5708
      recognition Recognition {
      }
    }
    Solid {
      children [
        Shape {
          appearance PBRAppearance {
            metalness 0
          }
          geometry Cone {
            bottomRadius 0.05
            height 0.1
          }
        }
      ]
    }
  ]
  controller "camera_node"
}
Solid {
  translation 1.28 0 0.58
  children [
    Shape {
      appearance PBRAppearance {
        roughness 0.3
        metalness 0
      }
      geometry DEF testObj Box {
        size 0.05 0.05 0.02
      }
    }
  ]
  boundingObject USE testObj
  physics Physics {
    density -1
    mass 0.1
  }
  recognitionColors [
    0.8 0.8 0.8
  ]
}
Solid {
  translation 1.49 0.06 0.58
  children [
    Shape {
      appearance PBRAppearance {
        roughness 0.3
        metalness 0
      }
      geometry DEF testObj Box {
        size 0.05 0.05 0.02
      }
    }
  ]
  name "solid(1)"
  boundingObject USE testObj
  physics Physics {
    density -1
    mass 0.1
  }
  recognitionColors [
    0.8 0.8 0.8
  ]
}
Solid {
  translation 1.62 -0.09 0.58
  children [
    Shape {
      appearance PBRAppearance {
        roughness 0.3
        metalness 0
      }
      geometry DEF testObj Box {
        size 0.05 0.05 0.02
      }
    }
  ]
  name "solid(12)"
  boundingObject USE testObj
  physics Physics {
    density -1
    mass 0.1
  }
  recognitionColors [
    0.8 0.8 0.8
  ]
}
Solid {
  translation 1.96 0.06 0.58
  children [
    Shape {
      appearance PBRAppearance {
        roughness 0.3
        metalness 0
      }
      geometry DEF testObj Box {
        size 0.05 0.05 0.02
      }
    }
  ]
  name "solid(2)"
  boundingObject USE testObj
  physics Physics {
    density -1
    mass 0.1
  }
  recognitionColors [
    0.8 0.8 0.8
  ]
}
Solid {
  translation 1.86 0 0.58
  children [
    Shape {
      appearance PBRAppearance {
        roughness 0.3
        metalness 0
      }
      geometry DEF testObj Box {
        size 0.05 0.05 0.02
      }
    }
  ]
  name "solid(4)"
  boundingObject USE testObj
  physics Physics {
    density -1
    mass 0.1
  }
  recognitionColors [
    0.8 0.8 0.8
  ]
}
Solid {
  translation 1.89 0.08 0.58
  children [
    Shape {
      appearance PBRAppearance {
        baseColor 0.7 0.5 0.9
        roughness 0.3
        metalness 0
      }
      geometry DEF testObj Box {
        size 0.05 0.05 0.02
      }
    }
  ]
  name "solid(8)"
  boundingObject USE testObj
  physics Physics {
    density -1
    mass 0.1
  }
  recognitionColors [
    0.7 0.5 0.9
  ]
}
Solid {
  translation 1.45 -0.04 0.58
  children [
    Shape {
      appearance PBRAppearance {
        baseColor 0.7 0.5 0.9
        roughness 0.3
        metalness 0
      }
      geometry DEF testObj Box {
        size 0.05 0.05 0.02
      }
    }
  ]
  name "solid(13)"
  boundingObject USE testObj
  physics Physics {
    density -1
    mass 0.1
  }
  recognitionColors [
    0.7 0.5 0.9
  ]
}
Solid {
  translation 1.77 0.06 0.58
  children [
    Shape {
      appearance PBRAppearance {
        roughness 0.3
        metalness 0
      }
      geometry DEF testObj Box {
        size 0.05 0.05 0.02
      }
    }
  ]
  name "solid(5)"
  boundingObject USE testObj
  physics Physics {
    density -1
    mass 0.1
  }
  recognitionColors [
    0.8 0.8 0.8
  ]
}
Solid {
  translation 1.99 -0.04 0.58
  children [
    Shape {
      appearance PBRAppearance {
        roughness 0.3
        metalness 0
      }
      geometry DEF testObj Box {
        size 0.05 0.05 0.02
      }
    }
  ]
  name "solid(9)"
  boundingObject USE testObj
  physics Physics {
    density -1
    mass 0.1
  }
  recognitionColors [
    0.8 0.8 0.8
  ]
}
Solid {
  translation 3.03 0 0.58
  children [
    Shape {
      appearance PBRAppearance {
        roughness 0.3
        metalness 0
      }
      geometry DEF testObj Box {
        size 0.05 0.05 0.02
      }
    }
  ]
  name "solid(14)"
  boundingObject USE testObj
  physics Physics {
    density -1
    mass 0.1
  }
  recognitionColors [
    0.8 0.8 0.8
  ]
}
Solid {
  translation 1.68 0.08 0.58
  children [
    Shape {
      appearance PBRAppearance {
        roughness 0.3
        metalness 0
      }
      geometry DEF testObj Box {
        size 0.05 0.05 0.02
      }
    }
  ]
  name "solid(6)"
  boundingObject USE testObj
  physics Physics {
    density -1
    mass 0.1
  }
  recognitionColors [
    0.8 0.8 0.8
  ]
}
Solid {
  translation 1.66 -0.01 0.58
  children [
    Shape {
      appearance PBRAppearance {
        roughness 0.3
        metalness 0
      }
      geometry DEF testObj Box {
        size 0.05 0.05 0.02
      }
    }
  ]
  name "solid(10)"
  boundingObject USE testObj
  physics Physics {
    density -1
    mass 0.1
  }
  recognitionColors [
    0.8 0.8 0.8
  ]
}
Solid {
  translation 1.58 0.06 0.58
  children [
    Shape {
      appearance PBRAppearance {
        roughness 0.3
        metalness 0
      }
      geometry DEF testObj Box {
        size 0.05 0.05 0.02
      }
    }
  ]
  name "solid(7)"
  boundingObject USE testObj
  physics Physics {
    density -1
    mass 0.1
  }
  recognitionColors [
    0.8 0.8 0.8
  ]
}
Solid {
  translation 1.58 -0.03 0.58
  children [
    Shape {
      appearance PBRAppearance {
        roughness 0.3
        metalness 0
      }
      geometry DEF testObj Box {
        size 0.05 0.05 0.02
      }
    }
  ]
  name "solid(11)"
  boundingObject USE testObj
  physics Physics {
    density -1
    mass 0.1
  }
  recognitionColors [
    0.8 0.8 0.8
  ]
}
Solid {
  translation 1.75 -0.03 0.58
  children [
    Shape {
      appearance PBRAppearance {
        baseColor 0.7 0.5 0.9
        roughness 0.3
        metalness 0
      }
      geometry DEF testObj Box {
        size 0.05 0.05 0.02
      }
    }
  ]
  name "solid(3)"
  boundingObject USE testObj
  physics Physics {
    density -1
    mass 0.1
  }
  recognitionColors [
    0.7 0.5 0.9
  ]
}
